<?xml version="1.0" encoding="utf-8"?>
<!-- This URDF was automatically created by SolidWorks to URDF Exporter! Originally created by Stephen Brawner (brawner@gmail.com) 
     Commit Version: 1.6.0-4-g7f85cfe  Build Version: 1.6.7995.38578
     For more information, please see http://wiki.ros.org/sw_urdf_exporter -->
<robot
  name="URDF_LEG_001_000_000">
  
  <link name="base_link">
  <inertial>
    <origin xyz="0.0 0.0 0.0" rpy="0 0.0 0"/>
    <mass value="0.0"/>
    <inertia ixx="0.0" ixy="0.0" ixz="0.0" iyy="0.0" iyz="0.0" izz="0.0"/>
  </inertial>
  </link>

  <link name="Link_rail_y">
  <inertial>
    <origin xyz="0.0 0.0 0.0" rpy="0 0.0 0"/>
    <mass value="0.0"/>
    <inertia ixx="0.0" ixy="0.0" ixz="0.0" iyy="0.0" iyz="0.0" izz="0.0"/>
  </inertial>
  </link>

  <link name="Link_foot">
  <inertial>
    <origin xyz="0.0 0.0 0.0" rpy="0 0.0 0"/>
    <mass value="0.0"/>
    <inertia ixx="0.0" ixy="0.0" ixz="0.0" iyy="0.0" iyz="0.0" izz="0.0"/>
  </inertial>
  </link>

  <link
    name="link_rail_x">
    <inertial>
      <origin
        xyz="-8.6308E-05 0.00018678 -0.0003901"
        rpy="0 0 0" />
      <mass
        value="0.37766" />
      <inertia
        ixx="0.00011183"
        ixy="-2.8019E-07"
        ixz="-7.2687E-08"
        iyy="6.5676E-05"
        iyz="-6.3886E-08"
        izz="0.00016094" />
    </inertial>
    <visual>
      <origin
        xyz="0 0 0"
        rpy="0 0 0" />
      <geometry>
        <mesh
          filename="../meshes/base_link.obj" />
      </geometry>
      <material
        name="">
        <color
          rgba="0.75294 0.75294 0.75294 1" />
      </material>
    </visual>
    <!-- <collision>
      <origin
        xyz="0 0 0"
        rpy="0 0 0" />
      <geometry>
        <mesh
          filename="../meshes/base_link.obj" />
      </geometry>
    </collision> -->
  </link>

  <link
    name="Link_Hip_Roll">
    <inertial>
      <origin
        xyz="0.0031858 -0.00028131 -0.066103"
        rpy="0 0 0" />
      <mass
        value="0.57342" />
      <inertia
        ixx="0.00062163"
        ixy="2.9372E-06"
        ixz="7.0911E-06"
        iyy="0.00036727"
        iyz="-6.1191E-07"
        izz="0.0003807" />
    </inertial>
    <visual>
      <origin
        xyz="0 0 0"
        rpy="0 0 0" />
      <geometry>
        <mesh
          filename="../meshes/Link_Hip_Roll.obj" />
      </geometry>
      <material
        name="">
        <color
          rgba="0.75294 0.75294 0.75294 1" />
      </material>
    </visual>
    <!-- <collision>
      <origin
        xyz="0 0 0"
        rpy="0 0 0" />
      <geometry>
        <mesh
          filename="../meshes/Link_Hip_Roll.obj" />
      </geometry>
    </collision> -->
  </link>

  <joint
    name="Joint_Hip_Roll"
    type="fixed">
    <origin
      xyz="0 0.026 0"
      rpy="1.5708 0 0" />
    <parent
      link="link_rail_x" />
    <child
      link="Link_Hip_Roll" />
    <axis
      xyz="0 0 0" />
  </joint>

  <link
    name="Link_Hip_Pitch">
    <inertial>
      <origin
        xyz="-0.015486 -0.00028849 -0.044683"
        rpy="0 0 0" />
      <mass
        value="0.75736" />
      <inertia
        ixx="0.00046734"
        ixy="-4.1662E-06"
        ixz="5.7732E-11"
        iyy="0.00093176"
        iyz="-1.0064E-05"
        izz="0.0012629" />
    </inertial>
    <visual>
      <origin
        xyz="0 0 0"
        rpy="0 0 0" />
      <geometry>
        <mesh
          filename="../meshes/Link_Hip_Pitch.obj" />
      </geometry>
      <material
        name="">
        <color
          rgba="0.75294 0.75294 0.75294 1" />
      </material>
    </visual>
    <!-- <collision>
      <origin
        xyz="0 0 0"
        rpy="0 0 0" />
      <geometry>
        <mesh
          filename="../meshes/Link_Hip_Pitch.obj" />
      </geometry>
    </collision> -->
  </link>

  <joint
    name="Joint_Hip_Pitch"
    type="revolute">
    <origin
      xyz="-0.0146 0 -0.072"
      rpy="-1.5708 0 -1.5708" />
    <parent
      link="Link_Hip_Roll" />
    <child
      link="Link_Hip_Pitch" />
    <axis
      xyz="0 0 -1" />
    <limit
      effort="16"
      velocity="41" />
  </joint>

  <link
    name="Link_Knee_Pitch">
    <inertial>
      <origin
        xyz="-0.044768 -0.0009312 -1.74E-10"
        rpy="0 0 0" />
      <mass
        value="0.11794" />
      <inertia
        ixx="1.8687E-05"
        ixy="5.2157E-06"
        ixz="-1.6589E-11"
        iyy="8.2185E-05"
        iyz="4.0735E-12"
        izz="9.8349E-05" />
    </inertial>
    <visual>
      <origin
        xyz="0 0 0"
        rpy="0 0 0" />
      <geometry>
        <mesh
          filename="../meshes/Link_Knee_Pitch.obj" />
      </geometry>
      <material
        name="">
        <color
          rgba="0.75294 0.75294 0.75294 1" />
      </material>
    </visual>
    <!-- <collision>
      <origin
        xyz="0 0 0"
        rpy="0 0 0" />
      <geometry>
        <mesh
          filename="../meshes/Link_Knee_Pitch.obj" />
      </geometry>
    </collision> -->
  </link>

  <joint
    name="Joint_Knee_Pitch"
    type="revolute">
    <origin
      xyz="-0.15 0 -0.0742"
      rpy="0 0 0" />
    <parent
      link="Link_Hip_Pitch" />
    <child
      link="Link_Knee_Pitch" />
    <axis
      xyz="0 0 -1" />
    <limit
      effort="16"
      velocity="41" />
  </joint>

 <joint
    name="rail_y"
    type="prismatic">
    <origin
      xyz="0 0 0"
      rpy="0 0 0" />
    <parent
      link="base_link" />
    <child
      link="Link_rail_y" />
    <axis
      xyz="0 1 0" />
    <limit
      lower="-1.5"
      upper="1.5" />
  </joint>

 <joint
    name="rail_x"
    type="prismatic">
    <origin
      xyz="0 0 0"
      rpy="0 0 0" />
    <parent
      link="Link_rail_y" />
    <child
      link="link_rail_x" />
    <axis
      xyz="1 0 0" />
    <limit
      lower="-1.5"
      upper="1.5" />
  </joint>

  <joint name="Knee_foot" type="fixed">
    <parent link="Link_Knee_Pitch" />
    <child link="Link_foot" />
    <origin xyz="-0.15 0.0 0.0" rpy="0.0 0.0 0.0"/>
  </joint>

  <!-- Add 4 transmission: knee, hip, x and y stabilizing rails -->

  <transmission type="SimpleTransmission" name="Knee_Torque">
    <actuator name="knee" />
    <joint name="Joint_Knee_Pitch" />
  </transmission>

  <transmission type="SimpleTransmission" name="Hip_Torque">
    <actuator name="hip" />
    <joint name="Joint_Hip_Pitch" />
  </transmission>

  <transmission type="SimpleTransmission" name="rail_y_trans">
    <actuator name="hip_y" />
    <joint name="rail_y" />
  </transmission>

  <transmission type="SimpleTransmission" name="rail_x_trans">
    <actuator name="hip_x" />
    <joint name="rail_x" />
  </transmission>

</robot>