<?xml version="1.0" encoding="utf-8"?>
<!-- This URDF was automatically created by SolidWorks to URDF Exporter! Originally created by Stephen Brawner (brawner@gmail.com) 
     Commit Version: 1.6.0-4-g7f85cfe  Build Version: 1.6.7995.38578
     For more information, please see http://wiki.ros.org/sw_urdf_exporter -->
<robot name="Simple_Leg_Hinge">
  <!-- Start with ground -->

  <link name="ground">
    <visual>
      <origin xyz="0 0 -1" />
      <geometry>
        <box size="20 20 2" />
      </geometry>
      <material name="green">
        <color rgba="0.11 .4 0.11 1" />
      </material>
    </visual>
    <!-- <collision>
      <origin xyz="0 0 -1" />
      <geometry>
        <box size="3 1 2" />
      </geometry>
    </collision> -->
  </link>

  <joint name="ground_is_world" type="fixed">
    <parent link="world"/>
    <child link="ground"/>
  </joint>

  <!-- Connect foot dummy to ground via a hinge in y -->

  <link name="foot_dummy">
    <inertial>
      <origin xyz="0.0 0.0 0.0" rpy="0.0 0.0 0.0"/>
      <mass value="0.0"/>
      <inertia ixx="0.0" ixy="0.0" ixz="0.0" iyy="0.0" iyz="0.0" izz="0.0"/>
    </inertial>
  </link>

  <joint name="foot_ground" type="revolute">
    <origin xyz="0.0 0.0 0.0" rpy="0.0 0.0 0.0"/>
    <parent link="ground"/>
    <child link="foot_dummy"/>
    <axis xyz="1 0.0 0.0"/>
    <limit lower="-1.570796327" upper="1.570796327"/>
  </joint>

<!-- Connect foot dummy to foot via a hinge in x -->

  <link name="foot">
    <inertial>
      <origin xyz="0.0 0.0 0.02" rpy="0.0 0.0 0.0"/>
      <mass value="0.020"/>
      <inertia ixx="3.2E-6" ixy="0.0" ixz="0.0" iyy="3.2E-6" iyz="0.0" izz="3.2E-6"/>
    </inertial>
    <visual>
      <origin xyz="0.0 0.0 0.02" rpy="0.0 0.0 0.0"/>
      <geometry>
        <sphere radius="0.02"/>
      </geometry>
      <material name="gray">
        <color rgba="0.25 0.53 0.96 1.0"/>
      </material>
    </visual>
  </link>

  <joint name="foot_lower" type="revolute">
    <origin xyz="0.0 0.0 0.0" rpy="0.0 0.0 0.0"/>
    <parent link="foot_dummy"/>
    <child link="foot"/>
    <axis xyz="0 1 0.0"/>
    <limit lower="-1.570796327" upper="1.570796327"/>
  </joint>

<!-- Connect Foot to lower leg -->
<!-- Lower leg, cylinder of 15cm weighing 150g -->

<link name="lower_leg">
  <inertial>
    <origin xyz="0.0 0.0 0.075" rpy="0.0 0.0 0.0"/>
    <mass value="0.150"/>
    <inertia ixx="2.9625E-4" ixy="0.0" ixz="0.0" iyy="2.9625E-4" iyz="0.0" izz="3E-5"/>
  </inertial>
  <visual>
    <origin xyz="0.0 0.0 0.075" rpy="0.0 0.0 0.0"/>
    <geometry>
      <cylinder radius="0.02" length="0.15"/>
    </geometry>
      <material name="gray">
        <color rgba="0.25 0.53 0.96 1.0"/>
      </material>
  </visual>
</link>

<joint name="foot_leg" type="fixed">
  <origin xyz="0.0 0.0 0.02" rpy="0.0 0.0 0.0"/>
  <parent link="foot"/>
  <child link="lower_leg"/>
</joint>

<!-- Connect lower leg to knee -->

 <link name="knee">
    <inertial>
      <origin xyz="0.0 0.0 0.0" rpy="0.0 1.570796327 0.0"/>
      <mass value="0.020"/>
      <inertia ixx="4.667E-6" ixy="0.0" ixz="0.0" iyy="4.667E-6" iyz="0.0" izz="4E-6"/>
    </inertial>
    <visual>
      <origin xyz="0.0 0.0 0.0" rpy="0.0 1.570796327 0.0"/>
      <geometry>
        <cylinder radius="0.02" length="0.04"/>
      </geometry>
      <material name="gray">
        <color rgba="0.25 0.53 0.96 1.0"/>
      </material>
    </visual>
  </link>

<joint name="knee" type="revolute">
  <origin xyz="0.0 0.0 0.17" rpy="0.0 0.0 0.0"/>
  <parent link="lower_leg"/>
  <child link="knee"/>
  <axis xyz="1 0.0 0.0"/>
<limit lower="-1.570796327" upper="1.570796327"/>
</joint>


<!-- Connect lower and upper leg -->
<!-- Upper leg identical to lower leg -->

<link name="upper_leg">
  <inertial>
    <origin xyz="0.0 0.0 0.075" rpy="0.0 0.0 0.0"/>
    <mass value="0.150"/>
    <inertia ixx="2.9625E-4" ixy="0.0" ixz="0.0" iyy="2.9625E-4" iyz="0.0" izz="3E-5"/>
  </inertial>
  <visual>
    <origin xyz="0.0 0.0 0.075" rpy="0.0 0.0 0.0"/>
    <geometry>
      <cylinder radius="0.02" length="0.15"/>
    </geometry>
    <material name="gray">
      <color rgba="0.25 0.53 0.96 1.0"/>
    </material>
  </visual>
</link>

<joint name="knee_upper" type="fixed">
  <origin xyz="0.0 0.0 0.02" rpy="0.0 0.0 0.0"/>
  <parent link="knee"/>
  <child link="upper_leg"/>
</joint>

<!-- Rail in x direction -->

<link name="hip">
  <inertial>
    <origin xyz="0.0 0.0 0.0" rpy="0.0 1.570796327 0.0"/>
    <mass value="0.02"/>
    <inertia ixx="4.667E-6" ixy="0.0" ixz="0.0" iyy="4.667E-6" iyz="0.0" izz="4E-6"/>
  </inertial>
  <visual>
    <origin xyz="0.0 0.0 0.0" rpy="0.0 1.570796327 0.0"/>
    <geometry>
      <cylinder radius="0.02" length="0.04"/>
    </geometry>
      <material name="gray">
        <color rgba="0.25 0.53 0.96 1.0"/>
      </material>
  </visual>
</link>

<joint name="Hip_Pitch" type="revolute">
  <origin xyz="0.0 0.0 0.17" rpy="0.0 0.0 0.0"/>
  <parent link="upper_leg"/>
  <child link="hip"/>
  <axis xyz="1 0.0 0.0"/>
  <limit lower="-1.570796327" upper="1.570796327"/>
</joint>

<!-- base link -->

<link name="torso">
  <inertial>
    <origin xyz="0.0 0.0 0.07" rpy="0.0 0.0 0.0"/>
    <mass value="0.150"/>
    <inertia ixx="1.2875E-4" ixy="0.0" ixz="0.0" iyy="1.2875E-4" iyz="0.0" izz="7.5E-6"/>
  </inertial>
  <visual>
    <origin xyz="0.0 0.0 0.07" rpy="0.0 0.0 0.0"/>
    <geometry>
      <cylinder radius="0.01" length="0.10"/>
    </geometry>
      <material name="gray">
        <color rgba="0.25 0.53 0.96 1.0"/>
      </material>
  </visual>
</link>

<joint name="Hip_roll" type="revolute">
  <origin xyz="0.0 0.0 0.0" rpy="0.0 0.0 0.0"/>
  <parent link="hip"/>
  <child link="torso"/>
  <axis xyz="0.0 1 0.0"/>
  <limit lower="-1.570796327" upper="1.570796327"/>
</joint>

<link name="base_link">
  <inertial>
    <origin xyz="0.0 0.0 0.0" rpy="0.0 0.0 0.0"/>
    <mass value="0.100"/>
    <inertia ixx="1.6E-5" ixy="0.0" ixz="0.0" iyy="1.6E-5" iyz="0.0" izz="1.6E-5"/>
  </inertial>
  <visual>
    <origin xyz="0.0 0.0 0.0" rpy="0.0 0.0 0.0"/>
    <geometry>
      <sphere radius="0.02"/>
    </geometry>
    <material name="gray">
      <color rgba="0.25 0.53 0.96 1.0"/>
    </material>
  </visual>
</link>

<joint name="fixed_torso" type="fixed">
  <origin xyz="0.0 0.0 0.13" rpy="0.0 0.0 0.0"/>
  <parent link="torso"/>
  <child link="base_link"/>
  <axis xyz="1 0.0 0.0"/>
</joint>

<!-- Add 3 transmissions: Knee, Hip pitch, Hip roll -->

<transmission type="SimpleTransmission" name="Knee_Torque">
  <actuator name="knee_trans" />
  <joint name="knee" />
</transmission>

<transmission type="SimpleTransmission" name="Hip_Torque_Pitch">
  <actuator name="Hip_Pitch" />
  <joint name="Hip_Pitch" />
</transmission>

<transmission type="SimpleTransmission" name="Hip_Torque_Roll">
  <actuator name="Hip_Roll" />
  <joint name="Hip_roll" />
</transmission>

</robot>