<?xml version="1.0" encoding="utf-8"?>
<!-- This URDF was automatically created by SolidWorks to URDF Exporter! Originally created by Stephen Brawner (brawner@gmail.com) 
     Commit Version: 1.6.0-4-g7f85cfe  Build Version: 1.6.7995.38578
     For more information, please see http://wiki.ros.org/sw_urdf_exporter -->
<robot
  name="URDF_LEG_001_000_000">
  <!-- <link
    name="base_link">
    <inertial>
      <origin
        xyz="-8.6308E-05 0.00018678 -0.0003901"
        rpy="0 0 0" />
      <mass
        value="0.37766" />
      <inertia
        ixx="0.00011183"
        ixy="-2.8019E-07"
        ixz="-7.2687E-08"
        iyy="6.5676E-05"
        iyz="-6.3886E-08"
        izz="0.00016094" />
    </inertial>
    <visual>
      <origin
        xyz="0 0 0"
        rpy="0 0 0" />
      <geometry>
        <mesh
          filename="../meshes/base_link.obj" />
      </geometry>
      <material
        name="">
        <color
          rgba="0.75294 0.75294 0.75294 1" />
      </material>
    </visual>
    <collision>
      <origin
        xyz="0 0 0"
        rpy="0 0 0" />
      <geometry>
        <mesh
          filename="../meshes/base_link.obj" />
      </geometry>
    </collision>
  </link> -->

  <link
    name="Link_Hip_Pitch">
    <inertial>
      <origin
        xyz="-0.015486 -0.00028849 -0.044683"
        rpy="0 0 0" />
      <mass
        value="0.75736" />
      <inertia
        ixx="0.00046734"
        ixy="-4.1662E-06"
        ixz="5.7732E-11"
        iyy="0.00093176"
        iyz="-1.0064E-05"
        izz="0.0012629" />
    </inertial>
    <visual>
      <origin
        xyz="0 0 0"
        rpy="0 0 0" />
      <geometry>
        <mesh
          filename="../meshes/Link_Hip_Pitch.obj" />
      </geometry>
      <material
        name="">
        <color
          rgba="0.75294 0.75294 0.75294 1" />
      </material>
    </visual>
    <collision>
      <origin
        xyz="0 0 0"
        rpy="0 0 0" />
      <geometry>
        <mesh
          filename="../meshes/Link_Hip_Pitch.obj" />
      </geometry>
    </collision>
  </link>
  <joint
    name="Joint_Hip_Pitch"
    type="revolute">
    <origin
      xyz="-0.0146 0 -0.072"
      rpy="-1.5708 0 -1.5708" />
    <parent
      link="Hip_Slider" />
    <child
      link="Link_Hip_Pitch" />
    <axis
      xyz="0 0 -1" />
    <limit
      effort="16"
      velocity="41" />
  </joint>
  <link
    name="Link_Knee_Pitch">
    <inertial>
      <origin
        xyz="-0.044768 -0.0009312 -1.74E-10"
        rpy="0 0 0" />
      <mass
        value="0.11794" />
      <inertia
        ixx="1.8687E-05"
        ixy="5.2157E-06"
        ixz="-1.6589E-11"
        iyy="8.2185E-05"
        iyz="4.0735E-12"
        izz="9.8349E-05" />
    </inertial>
    <visual>
      <origin
        xyz="0 0 0"
        rpy="0 0 0" />
      <geometry>
        <mesh
          filename="../meshes/Link_Knee_Pitch.obj" />
      </geometry>
      <material
        name="">
        <color
          rgba="0.75294 0.75294 0.75294 1" />
      </material>
    </visual>
    <collision>
      <origin
        xyz="0 0 0"
        rpy="0 0 0" />
      <geometry>
        <mesh
          filename="../meshes/Link_Knee_Pitch.obj" />
      </geometry>
    </collision>
  </link>
  <joint
    name="Joint_Knee_Pitch"
    type="revolute">
    <origin
      xyz="-0.15 0 -0.0742"
      rpy="0 0 0" />
    <parent
      link="Link_Hip_Pitch" />
    <child
      link="Link_Knee_Pitch" />
    <axis
      xyz="0 0 -1" />
    <limit
      effort="16"
      velocity="41" />
  </joint>

  <link name="ground">

    <visual>
      <origin xyz="0 0 -1" />
      <geometry>
        <box size="3 1 2" />
      </geometry>
      <material name="green">
        <color rgba="0 .5 0 1" />
      </material>
    </visual>

    <collision>
      <origin xyz="0 0 -1" />
      <geometry>
        <box size="3 1 2" />
      </geometry>
    </collision>
    
  </link>

  <joint name="ground_is_world" type="fixed">
    <parent link="world" />
    <child link="ground" />
  </joint>

  <!-- <joint name="base_is_world" type="fixed">
    <parent link="world" />
    <child link="base_link" />
  </joint> -->

  <transmission type="SimpleTransmission" name="Knee_Torque">
    <actuator name="knee" />
    <joint name="Joint_Knee_Pitch" />
  </transmission>

  <!-- <link name="top_base">

    <visual>
      <origin xyz="0 0.05 0" />
      <geometry>
        <box size="0.01 0.01 0.01 " />
      </geometry>
      <material name="greener">
        <color rgba="0 1 0 1" />
      </material>
    </visual>
    
  </link> -->

  <joint
    name="rail_prismatic"
    type="prismatic">
    <origin
      xyz="0 0 0"
      rpy="0 0 -1.5708" />
    <parent
      link="world" />
    <child
      link="slider" />
    <axis
      xyz="0 0 1" />
    <limit
      lower="0"
      upper="1.5"
      effort="0"
      velocity="0" />
  </joint>

<link
    name="slider">
    <inertial>
      <origin
        xyz="0.01039 -8.6308E-05 -0.00018678"
        rpy="0 0 0" />
      <mass
        value="0.37766" />
      <inertia
        ixx="0.00016094"
        ixy="7.2687E-08"
        ixz="-6.3886E-08"
        iyy="0.00011183"
        iyz="2.8019E-07"
        izz="6.5676E-05" />
    </inertial>
    <visual>
      <origin
        xyz="0 0 0"
        rpy="0 0 0" />
      <geometry>
        <mesh
          filename="../meshes/slider.obj" />
      </geometry>
      <material
        name="">
        <color
          rgba="0.75294 0.75294 0.75294 1" />
      </material>
    </visual>
    <collision>
      <origin
        xyz="0 0 0"
        rpy="0 0 0" />
      <geometry>
        <mesh
          filename="../meshes/slider.obj" />
      </geometry>
    </collision>
  </link>

    <!-- dummy link to allow collisions between body and leg -->
  <link name="Hip_Slider">
  <inertial>
    <origin xyz="0.0 0.0 0.0" rpy="0 0.0 0"/>
    <mass value="0.0"/>
    <inertia ixx="0.0" ixy="0.0" ixz="0.0" iyy="0.0" iyz="0.0" izz="0.0"/>
  </inertial>
  
  </link>

  <!-- dummy joint to allow collisions between body and leg -->
  <joint name="leg_parent_is_body" type="fixed">
    <parent link="slider" />
    <child link="Hip_Slider" />
  </joint>

 <!-- <joint name="foot" type="continuous">
  <origin xyz="0.0 0.0 0.0" rpy="0.0 0.0 0.0"/>
  <parent link="ground"/>
  <child link="Link_Knee_Pitch"/>
  <axis xyz="0 0.0 -1"/>
 </joint> -->

</robot>
