<?xml version="1.0"?>
<robot name="Acrobot">

    <link name="base">
        <inertial>
            <origin xyz="0 0 0" />
            <mass value="0" />
        </inertial>
        
        <visual>
            <origin xyz="0 0 0" />
            <geometry>
                <sphere radius="0.05" />
            </geometry>
            <material>
                <color rgba="1 0 0 1" />
            </material>
        </visual>
    </link>
    
    <link name="shoulder">
        <inertial>
            <origin xyz="0 0 -0.5" />
            <mass value="1" />
            <inertia ixx="1" ixy="0" ixz="0" iyy="0.083" iyz="0" izz="1"/>
        </inertial>
        
        <visual>
            <origin xyz="0 0 -0.5" />
            <geometry>
                <cylinder length="1" radius="0.01" />
            </geometry>
            <material>
                <color rgba="0 0 1 1" />
            </material>
        </visual>

    </link>
    
    <link name="elbow">
        <inertial>
            <origin xyz="0 0 -0.5" />
            <mass value="1" />
            <inertia ixx="1" ixy="0" ixz="0" iyy="0.33" iyz="0" izz="1"/>
        </inertial>
        
        <visual>
            <origin xyz="0 0 0" />
            <geometry>
                <sphere radius="0.05" />
            </geometry>
            <material>
                <color rgba="0 1 0 1" />
            </material>
        </visual>
        
        <visual>
            <origin xyz="0 0 -0.5" />
            <geometry>
                <cylinder length="1" radius="0.01" />
            </geometry>
            <material>
                <color rgba="0 1 0 1" />
            </material>
        </visual>
    </link>
    
  <joint name="base" type="fixed">
    <parent link="world" />
    <child link="base" />
    <axis xyz="0 1 0" />
  </joint>
  
  <joint name="theta0" type="continuous">
    <parent link="base" />
    <child link="shoulder" />
    <axis xyz="0 -1 0" />
    <origin xyz="0 0 0"/>
  </joint>
  
  <joint name="theta1" type="continuous">
    <parent link="shoulder" />
    <child link="elbow" />
    <axis xyz="0 -1 0" />
    <origin xyz="0 0 -1.0"/>
  </joint>
  
  <transmission type="SimpleTransmission" name="elbow_torque">
    <actuator name="torque" />
    <joint name="theta1" />
  </transmission>
  
</robot>